Workbook

Sheet 문항카드 생성
C2: 2026 | D2: 학년도 | G2: 정답분포 | I2: 범위
C3: 3 | D3: 회고사
C4: 문항 카드 작성 | G4: ① | H4: =COUNTIF($H$11:$H$1048576,1) -> 0 | I4: 시공간과 운동
D5: 상 | E5: 중 | F5: 하 | G5: ② | H5: =COUNTIF($H$11:$H$1048576,2) -> 0
C6: 난이도 | D6: 8 | E6: 8 | F6: 8 | G6: ③ | H6: =COUNTIF($H$11:$H$1048576,3) -> 0 | I6: ~
C7: 현황 | D7: =COUNTIF($F$11:$F$1048576,"상") -> 0 | E7: =COUNTIF($F$11:$F$1048576,"중") -> 0 | F7: =COUNTIF($F$11:$F$1048576,"하") -> 0 | G7: ④ | H7: =COUNTIF($H$11:$H$1048576,4) -> 0
C8: 목표 | D8: =D6+E6+F6 -> 24 | E8: 현황 | F8: =D7+E7+F7 -> 0 | G8: ⑤ | H8: =COUNTIF($H$11:$H$1048576,5) -> 0 | N8: 배점 합 | O8: =SUM(O11:O34) -> 100
B10: 번호 | C10: 성취기준 코드 | D10: 성취기준명 | E10: 성취기준 해설 | F10: 난이도 | G10: 문항 유형 | H10: 답 | I10: 문항 핵심 아이디어 | J10: [문두] | K10: [자료] | L10: [발문] | M10: [보기] | N10: [답지] | O10: 배점 | P10: 예상 난도(교정) | Q10: 예상 변별도(교정) | R10: 기존 번호
B11: 1 | D11: =IF(VLOOKUP(C11,'성취기준(22개정)'!$C$3:$E$507,2,0)=0,"",VLOOKUP(C11,'성취기준(22개정)'!$C$3:$E$507,2,0)) -> #N/A | E11: =IF(VLOOKUP(C11,'성취기준(22개정)'!$C$3:$E$507,3,0)=0,"",VLOOKUP(C11,'성취기준(22개정)'!$C$3:$E$507,3,0)) -> #N/A | O11: 3.2
B12: 2 | D12: =IF(VLOOKUP(C12,'성취기준(22개정)'!$C$3:$E$507,2,0)=0,"",VLOOKUP(C12,'성취기준(22개정)'!$C$3:$E$507,2,0)) -> #N/A | E12: =IF(VLOOKUP(C12,'성취기준(22개정)'!$C$3:$E$507,3,0)=0,"",VLOOKUP(C12,'성취기준(22개정)'!$C$3:$E$507,3,0)) -> #N/A | O12: 3.3
B13: 3 | D13: =IF(VLOOKUP(C13,'성취기준(22개정)'!$C$3:$E$507,2,0)=0,"",VLOOKUP(C13,'성취기준(22개정)'!$C$3:$E$507,2,0)) -> #N/A | E13: =IF(VLOOKUP(C13,'성취기준(22개정)'!$C$3:$E$507,3,0)=0,"",VLOOKUP(C13,'성취기준(22개정)'!$C$3:$E$507,3,0)) -> #N/A | O13: 3.4
B14: 4 | D14: =IF(VLOOKUP(C14,'성취기준(22개정)'!$C$3:$E$507,2,0)=0,"",VLOOKUP(C14,'성취기준(22개정)'!$C$3:$E$507,2,0)) -> #N/A | E14: =IF(VLOOKUP(C14,'성취기준(22개정)'!$C$3:$E$507,3,0)=0,"",VLOOKUP(C14,'성취기준(22개정)'!$C$3:$E$507,3,0)) -> #N/A | O14: 3.5
B15: 5 | D15: =IF(VLOOKUP(C15,'성취기준(22개정)'!$C$3:$E$507,2,0)=0,"",VLOOKUP(C15,'성취기준(22개정)'!$C$3:$E$507,2,0)) -> #N/A | E15: =IF(VLOOKUP(C15,'성취기준(22개정)'!$C$3:$E$507,3,0)=0,"",VLOOKUP(C15,'성취기준(22개정)'!$C$3:$E$507,3,0)) -> #N/A | O15: 3.6
B16: 6 | D16: =IF(VLOOKUP(C16,'성취기준(22개정)'!$C$3:$E$507,2,0)=0,"",VLOOKUP(C16,'성취기준(22개정)'!$C$3:$E$507,2,0)) -> #N/A | E16: =IF(VLOOKUP(C16,'성취기준(22개정)'!$C$3:$E$507,3,0)=0,"",VLOOKUP(C16,'성취기준(22개정)'!$C$3:$E$507,3,0)) -> #N/A | O16: 3.6
B17: 7 | D17: =IF(VLOOKUP(C17,'성취기준(22개정)'!$C$3:$E$507,2,0)=0,"",VLOOKUP(C17,'성취기준(22개정)'!$C$3:$E$507,2,0)) -> #N/A | E17: =IF(VLOOKUP(C17,'성취기준(22개정)'!$C$3:$E$507,3,0)=0,"",VLOOKUP(C17,'성취기준(22개정)'!$C$3:$E$507,3,0)) -> #N/A | O17: 3.7
B18: 8 | D18: =IF(VLOOKUP(C18,'성취기준(22개정)'!$C$3:$E$507,2,0)=0,"",VLOOKUP(C18,'성취기준(22개정)'!$C$3:$E$507,2,0)) -> #N/A | E18: =IF(VLOOKUP(C18,'성취기준(22개정)'!$C$3:$E$507,3,0)=0,"",VLOOKUP(C18,'성취기준(22개정)'!$C$3:$E$507,3,0)) -> #N/A | O18: 3.8
B19: 9 | D19: =IF(VLOOKUP(C19,'성취기준(22개정)'!$C$3:$E$507,2,0)=0,"",VLOOKUP(C19,'성취기준(22개정)'!$C$3:$E$507,2,0)) -> #N/A | E19: =IF(VLOOKUP(C19,'성취기준(22개정)'!$C$3:$E$507,3,0)=0,"",VLOOKUP(C19,'성취기준(22개정)'!$C$3:$E$507,3,0)) -> #N/A | O19: 3.9
B20: 10 | D20: =IF(VLOOKUP(C20,'성취기준(22개정)'!$C$3:$E$507,2,0)=0,"",VLOOKUP(C20,'성취기준(22개정)'!$C$3:$E$507,2,0)) -> #N/A | E20: =IF(VLOOKUP(C20,'성취기준(22개정)'!$C$3:$E$507,3,0)=0,"",VLOOKUP(C20,'성취기준(22개정)'!$C$3:$E$507,3,0)) -> #N/A | O20: 4
B21: 11 | D21: =IF(VLOOKUP(C21,'성취기준(22개정)'!$C$3:$E$507,2,0)=0,"",VLOOKUP(C21,'성취기준(22개정)'!$C$3:$E$507,2,0)) -> #N/A | E21: =IF(VLOOKUP(C21,'성취기준(22개정)'!$C$3:$E$507,3,0)=0,"",VLOOKUP(C21,'성취기준(22개정)'!$C$3:$E$507,3,0)) -> #N/A | O21: 4.1
B22: 12 | D22: =IF(VLOOKUP(C22,'성취기준(22개정)'!$C$3:$E$507,2,0)=0,"",VLOOKUP(C22,'성취기준(22개정)'!$C$3:$E$507,2,0)) -> #N/A | E22: =IF(VLOOKUP(C22,'성취기준(22개정)'!$C$3:$E$507,3,0)=0,"",VLOOKUP(C22,'성취기준(22개정)'!$C$3:$E$507,3,0)) -> #N/A | O22: 4.2
... B34: 24 | D34: =IF(VLOOKUP(C34,'성취기준(22개정)'!$C$3:$E$507,2,0)=0,"",VLOOKUP(C34,'성취기준(22개정)'!$C$3:$E$507,2,0)) -> #N/A | E34: =IF(VLOOKUP(C34,'성취기준(22개정)'!$C$3:$E$507,3,0)=0,"",VLOOKUP(C34,'성취기준(22개정)'!$C$3:$E$507,3,0)) -> #N/A | O34: 5.1
B35: 25 | D35: =IF(VLOOKUP(C35,'성취기준(22개정)'!$C$3:$E$507,2,0)=0,"",VLOOKUP(C35,'성취기준(22개정)'!$C$3:$E$507,2,0)) -> #N/A | E35: =IF(VLOOKUP(C35,'성취기준(22개정)'!$C$3:$E$507,3,0)=0,"",VLOOKUP(C35,'성취기준(22개정)'!$C$3:$E$507,3,0)) -> #N/A
B36: 26 | D36: =IF(VLOOKUP(C36,'성취기준(22개정)'!$C$3:$E$507,2,0)=0,"",VLOOKUP(C36,'성취기준(22개정)'!$C$3:$E$507,2,0)) -> #N/A | E36: =IF(VLOOKUP(C36,'성취기준(22개정)'!$C$3:$E$507,3,0)=0,"",VLOOKUP(C36,'성취기준(22개정)'!$C$3:$E$507,3,0)) -> #N/A
B37: 27 | D37: =IF(VLOOKUP(C37,'성취기준(22개정)'!$C$3:$E$507,2,0)=0,"",VLOOKUP(C37,'성취기준(22개정)'!$C$3:$E$507,2,0)) -> #N/A | E37: =IF(VLOOKUP(C37,'성취기준(22개정)'!$C$3:$E$507,3,0)=0,"",VLOOKUP(C37,'성취기준(22개정)'!$C$3:$E$507,3,0)) -> #N/A
B38: 28 | D38: =IF(VLOOKUP(C38,'성취기준(22개정)'!$C$3:$E$507,2,0)=0,"",VLOOKUP(C38,'성취기준(22개정)'!$C$3:$E$507,2,0)) -> #N/A | E38: =IF(VLOOKUP(C38,'성취기준(22개정)'!$C$3:$E$507,3,0)=0,"",VLOOKUP(C38,'성취기준(22개정)'!$C$3:$E$507,3,0)) -> #N/A
B39: 29 | D39: =IF(VLOOKUP(C39,'성취기준(22개정)'!$C$3:$E$507,2,0)=0,"",VLOOKUP(C39,'성취기준(22개정)'!$C$3:$E$507,2,0)) -> #N/A | E39: =IF(VLOOKUP(C39,'성취기준(22개정)'!$C$3:$E$507,3,0)=0,"",VLOOKUP(C39,'성취기준(22개정)'!$C$3:$E$507,3,0)) -> #N/A
B40: 30 | D40: =IF(VLOOKUP(C40,'성취기준(22개정)'!$C$3:$E$507,2,0)=0,"",VLOOKUP(C40,'성취기준(22개정)'!$C$3:$E$507,2,0)) -> #N/A | E40: =IF(VLOOKUP(C40,'성취기준(22개정)'!$C$3:$E$507,3,0)=0,"",VLOOKUP(C40,'성취기준(22개정)'!$C$3:$E$507,3,0)) -> #N/A
B41: 31 | D41: =IF(VLOOKUP(C41,'성취기준(22개정)'!$C$3:$E$507,2,0)=0,"",VLOOKUP(C41,'성취기준(22개정)'!$C$3:$E$507,2,0)) -> #N/A | E41: =IF(VLOOKUP(C41,'성취기준(22개정)'!$C$3:$E$507,3,0)=0,"",VLOOKUP(C41,'성취기준(22개정)'!$C$3:$E$507,3,0)) -> #N/A
B42: 32 | D42: =IF(VLOOKUP(C42,'성취기준(22개정)'!$C$3:$E$507,2,0)=0,"",VLOOKUP(C42,'성취기준(22개정)'!$C$3:$E$507,2,0)) -> #N/A | E42: =IF(VLOOKUP(C42,'성취기준(22개정)'!$C$3:$E$507,3,0)=0,"",VLOOKUP(C42,'성취기준(22개정)'!$C$3:$E$507,3,0)) -> #N/A
B43: 33 | D43: =IF(VLOOKUP(C43,'성취기준(22개정)'!$C$3:$E$507,2,0)=0,"",VLOOKUP(C43,'성취기준(22개정)'!$C$3:$E$507,2,0)) -> #N/A | E43: =IF(VLOOKUP(C43,'성취기준(22개정)'!$C$3:$E$507,3,0)=0,"",VLOOKUP(C43,'성취기준(22개정)'!$C$3:$E$507,3,0)) -> #N/A
B44: 34 | D44: =IF(VLOOKUP(C44,'성취기준(22개정)'!$C$3:$E$507,2,0)=0,"",VLOOKUP(C44,'성취기준(22개정)'!$C$3:$E$507,2,0)) -> #N/A | E44: =IF(VLOOKUP(C44,'성취기준(22개정)'!$C$3:$E$507,3,0)=0,"",VLOOKUP(C44,'성취기준(22개정)'!$C$3:$E$507,3,0)) -> #N/A
B45: 35 | D45: =IF(VLOOKUP(C45,'성취기준(22개정)'!$C$3:$E$507,2,0)=0,"",VLOOKUP(C45,'성취기준(22개정)'!$C$3:$E$507,2,0)) -> #N/A | E45: =IF(VLOOKUP(C45,'성취기준(22개정)'!$C$3:$E$507,3,0)=0,"",VLOOKUP(C45,'성취기준(22개정)'!$C$3:$E$507,3,0)) -> #N/A
B46: 36 | D46: =IF(VLOOKUP(C46,'성취기준(22개정)'!$C$3:$E$507,2,0)=0,"",VLOOKUP(C46,'성취기준(22개정)'!$C$3:$E$507,2,0)) -> #N/A | E46: =IF(VLOOKUP(C46,'성취기준(22개정)'!$C$3:$E$507,3,0)=0,"",VLOOKUP(C46,'성취기준(22개정)'!$C$3:$E$507,3,0)) -> #N/A
... B110: 100 | D110: =IF(VLOOKUP(C110,'성취기준(22개정)'!$C$3:$E$507,2,0)=0,"",VLOOKUP(C110,'성취기준(22개정)'!$C$3:$E$507,2,0)) -> #N/A | E110: =IF(VLOOKUP(C110,'성취기준(22개정)'!$C$3:$E$507,3,0)=0,"",VLOOKUP(C110,'성취기준(22개정)'!$C$3:$E$507,3,0)) -> #N/A

Sheet 성취기준(22개정)
B2: 연번 | C2: 성취기준 코드 | D2: 성취기준명 | E2: 성취기준 해설
B3: 1 | C3: [9과01-01] | D3: 과학적 탐구 방법을 이해하고, 일상생활의 문제에 대한 과학적 해결 방안을 제안할 수 있다. | E3: 간단한 탐구 실험을 제시하여 탐구 절차 및 방법을 익히도록 하며, 학생이 스스로 발견한 문제를 일정 기간 동안 지속적으로 탐구하여 해결해 보는 기회를 제공할 수 있다.
B4: 2 | C4: [9과01-02] | D4: 과학의 발전이 인류 문명에 미친 영향을 이해하고, 인공지능 등 첨단 과학기술이 가져올 미래 사회의 변화를 조사하여 발표할 수 있다. | E4: 과학적 탐구 방법을 통해 얻은 과학 지식과 방법이 인류 문명과 문화 발달에 미친 영향을 중심으로 학습하고, 원리보다는 활용 측면에서 첨단 과학기술 사례를 함께 다룬다.
B5: 3 | C5: [9과01-03] | D5: 인류의 지속가능한 삶을 위한 과학기술의 중요성과 역할에 대해 토의하고, 개인과 사회 차원의 활동 방안을 찾아 실천할 수 있다.
B6: 4 | C6: [9과02-01] | D6: 세포는 생명 활동이 일어나는 기본 단위임을 이해하고, 세포의 구조와 기능의 관계를 추론할 수 있다. | E6: 세포의 구조는 세포벽, 세포막, 핵, 엽록체, 미토콘드리아를, 세포의 특징으로는 생명 활동을 유추할 수 있는 세포(적혈구, 신경세포, 상피세포 등)를 다룬다.
B7: 5 | C7: [9과02-02] | D7: 생물의 유기적 구성 단계를 이해하고, 동물과 식물을 비교하여 분석할 수 있다. | E7: 분광기를 활용하여 수소의 선스펙트럼을 관찰하고 이를 우주 전역의 선스펙트럼을 관찰한 결과 자료와 비교함으로써 우주 진화 초기에 만들어진 수소와 헬륨이 현재 우주의 주요 구성 원소임을 파악하게 한다.
B8: 6 | C8: [9과02-03] | D8: 생물다양성을 이해하고, 변이와 생물다양성의 관계를 추론할 수 있다. | E8: 별의 진화 과정에서 별 내부의 핵융합을 통해 탄소, 질소, 산소가 생성되는 것을 정성적으로 다루고, 초신성 폭발의 결과로 철보다 무거운 원소가 만들어짐을 다룬다.
B9: 7 | C9: [9과02-04] | D9: 종의 개념과 분류 체계를 이해하고, 생물을 계 수준에서 분류할 수 있다. | E9: 종은 생물학적 종 개념만을, 생물 분류 체계는 5계만을 다루도록 한다.
B10: 8 | C10: [9과02-05] | D10: 생물다양성 보전의 필요성을 이해하고, 생물다양성 유지를 위한 방안을 조사하고 실천할 수 있다. | E10: 각 화학 결합으로 나타나는 성질은 전기 전도성에 한정하여 다룬다.
B11: 9 | C11: [9과03-01] | D11: 온도와 열평형 과정을 물질을 구성하는 입자들의 배치나 움직임 등으로 설명할 수 있다. | E11: 온도가 다른 두 물체가 열평형에 도달하는 과정을 시간-온도 그래프 등을 활용하여 설명할 수 있도록 한다.
B12: 10 | C12: [9과03-02] | D12: 열은 전도, 대류, 복사로 전달됨을 알고, 열전달 과정을 모형 등을 사용하여 다양하게 표현할 수 있다. | E12: 열의 이동 방식을 주변 도구나 신체를 이용하여 비유적으로 다양하게 표현하고, 그 차이를 설명할 수 있도록 한다.
B13: 11 | C13: [9과03-03] | D13: 물질에 따라 비열과 열팽창 정도가 다름을 알고, 이러한 성질이 일상생활에서 유용하게 활용됨을 인식할 수 있다. | E13: 지구시스템을 구성하는 권역들의 성층구조를 파악하게 한다. 기권, 수권 등 각 권역이 상호작용하는 과정의 에너지 흐름과 물질 순환으로 인해 지표의 변화, 날씨의 변화 등과 같은 여러 가지 과학적 현상이 일어남을 다룬다.
B14: 12 | C14: [9과04-01] | D14: 확산 및 증발 현상을 관찰하여 물질을 구성하는 입자가 운동하고 있음을 추론할 수 있다. | E14: 지구시스템을 구성하는 권역들의 성층구조를 파악하게 한다. 기권, 수권 등 각 권역이 상호작용하는 과정의 에너지 흐름과 물질 순환으로 인해 지표의 변화, 날씨의 변화 등과 같은 여러 가지 과학적 현상이 일어남을 다룬다.
B15: 13 | C15: [9과04-02] | D15: 물질의 세 가지 상태의 특징을 설명하고, 이를 입자 모형으로 표현할 수 있다. | E15: 물질의 상태를 나타내는 입자 모형은 입자 사이의 상대적 거리, 입자 배열의 불규칙한 정도, 입자의 운동성 등을 비교한 내용을 포함한다.
B16: 14 | C16: [9과04-03] | D16: 여러 가지 물질의 상태 변화를 관찰하고, 이를 입자 모형으로 설명할 수 있다. | E16: 여러 가지 물질의 상태 변화를 관찰하여 융해, 응고, 기화, 액화, 승화를 구분하고, 물질의 상태가 변할 때 부피는 변하고 질량과 물질의 성질은 변하지 않는 이유를 입자 모형으로 설명한다.
B17: 15 | C17: [9과04-04] | D17: 물질의 상태 변화와 열에너지 출입 관계를 이해하고, 이를 실생활에 적용하여 과학의 유용성을 인식할 수 있다. | E17: 물질의 상태 변화 시 온도가 일정한 이유를 상태 변화 과정에서 출입하는 열에너지와 관련지어 설명한다.
... B25: 23 | C25: [9과07-01] | D25: 태양계를 구성하는 천체의 특징을 알고, 행성을 목성형 행성과 지구형 행성으로 구분할 수 있다. | E25: 태양계를 구성하는 천체인 태양, 행성, 왜소행성, 소행성, 위성, 혜성을 개괄적으로 학습하며, 자세한 특징은 다루지 않는다.
B26: 24 | C26: [9과07-02] | D26: 태양의 표면과 대기에서 일어나는 현상을 알고, 태양의 활동이 지구에 미치는 영향을 추론할 수 있다.
B27: 25 | C27: [9과07-03] | D27: 지구 자전에 의한 천체의 겉보기 운동과 지구 공전에 의한 별자리 변화를 이해하고, 밤하늘 천체에 호기심을 가진다. | E27: 관측자의 위치(고위도, 저위도, 중위도)에 따른 일주운동은 다루지 않는다. 지구의 자전과 공전을 우주에서 바라보는 관점으로 설명한다.
B28: 26 | C28: [9과07-04] | D28: 달을 관측하여 달의 위상변화 원리를 이해하고, 일식과 월식을 설명할 수 있다. | E28: 코일을 통과하는 자기장의 세기가 변할 때 유도되는 전류를 관찰하여 전자기 유도 현상을 정성적으로 이해하고, 이를 이용한 간이 발전기를 만들어 발전소에서 전기 에너지를 만드는 방법을 설명한다.
B29: 27 | C29: [9과08-01] | D29: 물질의 특성의 의미를 알고, 실험을 통해 밀도, 용해도, 녹는점, 끓는점 등을 설명할 수 있다. | E29: 물질의 특성은 특정한 조건에서 항상 일정한 값을 가지며 물질의 양에 따라 달라지지 않는 것으로 물질을 구분하는 중요한 정보가 됨을 이해하고, 그 사례로 밀도, 용해도, 녹는점, 끓는점 등이 있음을 다룬다.
B30: 28 | C30: [9과08-02] | D30: 물질의 특성을 근거로 우리 주변의 물질을 순물질과 혼합물로 분류할 수 있다.
B31: 29 | C31: [9과08-03] | D31: 물질의 특성을 이용하여 혼합물이 분리되는 원리를 이해하고, 이를 이용한 사례를 주변에서 찾을 수 있다. | E31: 과학 실험, 기상 관측, 유전체 분석, 신약 개발 등과 같은 분야에서 많은 정보를 디지털 형태로 전환하여 대량의 데이터를 축적할 수 있게 되면서, 일상생활의 다양한 분야에서 폭넓게 활용할 수 있음을 소개한다.
B32: 30 | C32: [9과09-01] | D32: 지구계의 구성 요소를 알고, 지권의 층상 구조와 그 특징을 조사⋅발표할 수 있다. | E32: 지구계의 구성 요소 및 지권을 구성하는 각 층의 명칭과 상태만 다루며, 지구 내부구조 탐사에서 지진파의 특성은 다루지 않는다.
B33: 31 | C33: [9과09-02] | D33: 조암 광물의 주요 특성을 관찰하고, 암석과 광물의 활용 방안 및 자원으로서 가치에 대해 조사할 수 있다. | E33: 광물의 특성은 색, 조흔색, 굳기, 염산 반응, 자성만 다루고, 굳기는 방해석과 석영 정도만 비교하여 제시한다.
B34: 32 | C34: [9과09-03] | D34: 지각을 이루는 암석을 생성 과정에 따라 분류하고, 암석의 순환 과정을 설명할 수 있다. | E34: 지각에 분포하는 다양한 암석 중, 화성암은 현무암, 유문암, 화강암, 반려암을, 퇴적암은 이암, 사암, 역암, 석회암을, 변성암은 편암, 편마암, 대리암, 규암만을 대표적으로 다룬다.
B35: 33 | C35: [9과09-04] | D35: 풍화 과정을 이해하고, 토양 생성 과정을 풍화 작용의 예로 설명할 수 있다. | E35: 과학자들의 꾸준한 노력과 함께 과학자의 우연한 발견 등을 통한 과학 지식 도출과 과학 지식의 잠정성 등 다양한 사례를 통해 과학의 본성을 체험할 기회를 제공하고, 우리 선조들의 과학 기술 발전의 사례도 찾아본다.
B36: 34 | C36: [9과09-05] | D36: 대륙이동설을 이해하고, 지진과 화산이 발생하는 지역의 분포를 판의 경계와 관련지어 설명할 수 있다. | E36: 화산대와 지진대의 분포가 판의 경계와 일치한다는 정도만 다루고, 판의 경계에서 나타나는 다양한 지질학적 특성은 고등학교 ‘지구과학’에서 다룬다.
B37: 35 | C37: [9과10-01] | D37: 빛의 반사와 굴절의 원리를 이해하고, 물체를 보는 과정을 빛의 경로를 이용하여 표현할 수 있다. | E37: 실험을 통해 빛의 반사, 굴절의 특징을 확인하고, 굴절 법칙은 정량적으로 다루지 않는다.
B38: 36 | C38: [9과10-02] | D38: 평면거울에서 상이 생기는 원리를 설명하고, 일상생활에서 사용되는 거울과 렌즈의 종류를 분류하고 상의 특징을 비교할 수 있다. | E38: 상이 생기는 원리는 평면거울에 의한 상만을 빛의 반사 법칙을 적용하여 이해하도록 한다. 다양한 거울과 렌즈에 의해 생기는 상의 위치나 크기를 정량적으로 계산하거나 실상과 허상을 구분하는 활동은 하지 않고, 정성적인 특징을 다양한 예를 통해 비교하도록 한다.
B39: 37 | C39: [9과10-03] | D39: 물체의 색을 빛의 반사와 관련지어 설명하고, 영상 장치에서 빛의 합성을 이용하여 다양한 색이 표현되는 원리를 이해할 수 있다.
B40: 38 | C40: [9과10-04] | D40: 파동의 발생과 전달 과정을 이해하고, 소리의 특성을 진폭, 진동수, 파형 등의 과학적 용어로 표현할 수 있다. | E40: 소리는 파동의 일종으로 매질을 통해 전달됨을 설명하고, 다양한 소리의 파형을 비교하여 파동의 진폭, 진동수, 파장의 개념을 설명하도록 한다. 종파와 횡파를 구분하여 설명하지는 않는다.
B41: 39 | C41: [9과11-01] | D41: 원소와 화합물의 정의를 알고, 원소와 화합물을 화학식으로 표현할 수 있다. | E41: ‘통합과학1’과 ‘통합과학2'에 제시된 일상생활과 관련된 탐구 주제 및 활동을 중심으로 사회적 현상과 이슈에서 문제를 찾고, 연구 윤리와 안전 사항을 준수하여 과학 탐구의 전체 과정을 수행하며, 해결책을 다양한 표상을 통해 산출하도록 한다.
B42: 40 | C42: [9과11-02] | D42: 원소를 구성하는 입자인 원자는 양성자, 중성자, 전자로 구성되며, 양성자의 수에 따라 원소의 종류가 달라짐을 입자 모형을 활용하여 설명할 수 있다. | E42: 질량수나 동위 원소는 다루지 않는다.
B43: 41 | C43: [9과11-03] | D43: 원소는 양성자의 수에 따라 주기율표에 배치됨을 알고, 주기율표에서 성질이 유사한 원소를 찾을 수 있다. | E43: 동족 원소의 유사성은 1족 원소의 물과의 반응성, 18족 원소의 안정성 등 비슷한 성질을 지닌 원소들이 있음을 탐구를 통해 추론하고, 각 반응에 관한 구체적 설명이나 원리 및 원소의 주기성은 다루지 않는다.
B44: 42 | C44: [9과11-04] | D44: 물질을 이루는 입자는 원자, 분자, 이온 등으로 존재할 수 있음을 알고, 이온은 전하를 띠고 있음을 설명할 수 있다. | E44: 이온의 경우 원자가 전기적으로 중성임을 토대로 전자를 잃으면 양이온이 되고, 전자를 얻으면 음이온이 된다는 수준에서 다룬다.
B45: 43 | C45: [9과12-01] | D45: 광합성 과정을 이해하고, 환경 요인과 광합성의 관계를 탐구하는 실험을 설계할 수 있다. | E45: 자원탐사 및 정주 공간 확보를 위한 우주개발 사례 조사 등의 활동을 통해 미래 과학기술의 발전 방향, 과학기술 이용과 관련된 환경정의, 안전 사항을 점검할 기회를 제공한다.
B46: 44 | C46: [9과12-02] | D46: 식물의 호흡과 광합성의 관계를 이해하고, 호흡과 광합성 과정에서 출입하는 에너지와 물질의 변화를 분석할 수 있다. | E46: 일상생활에서 접할 수 있는 다양한 상황에서 돌림힘을 적용하되, 동역학적 상황이나 돌림힘의 기준점이 2개 이상이 되는 등 현실에서 찾기 힘든 복잡한 상황은 다루지 않는다.
B47: 45 | C47: [9과12-03] | D47: 광합성 산물의 저장과 이용 과정을 이해하고, 모형으로 설명할 수 있다. | E47: 광합성 결과 만들어진 산물은 생명 활동에 필요한 에너지원임을 강조하여 다룬다.
B48: 46 | C48: [9과13-01] | D48: 소화계의 구조와 기능을 이해하고, 소화 과정을 소화 효소의 작용과 관련지어 추론할 수 있다. | E48: 소화 기관에서 일어나는 소화 과정은 아밀레이스, 펩신, 트립신, 라이페이스 등 대표적인 몇 가지 소화 효소 중심으로 간단하게 언급한다.
...
